#VRML_SIM R2025a utf8

EXTERNPROTO "https://raw.githubusercontent.com/cyberbotics/webots/R2025a/projects/objects/floors/protos/RectangleArena.proto"
EXTERNPROTO "https://raw.githubusercontent.com/cyberbotics/webots/R2025a/projects/objects/backgrounds/protos/TexturedBackground.proto"
EXTERNPROTO "https://raw.githubusercontent.com/cyberbotics/webots/R2025a/projects/objects/backgrounds/protos/TexturedBackgroundLight.proto"

WorldInfo {
}
Viewpoint {
  orientation 0.027635614596645017 0.9134099787612623 -0.406101567966951 0.1486269953067906
  position -14.290129240747302 -0.08352093151977036 4.131787552438641
}
RectangleArena {
  floorSize 30 50
  wallThickness 0.3
  wallHeight 6
}
TexturedBackground {
}
TexturedBackgroundLight {
}
Robot {
  translation 0 0 1
  children [
    HingeJoint {
      jointParameters HingeJointParameters {
        axis 0 1 0
        anchor -0.5 0.4 -0.15
      }
      device [
        RotationalMotor {
          name "motor_fl"
        }
      ]
      endPoint Solid {
        translation -0.4999999999999999 0.4000000000000002 -0.15000000000000036
        rotation 0.5773489358556709 0.5773509358554486 0.5773509358554485 2.0943999999999994
        children [
          DEF WHEEL Shape {
            appearance PBRAppearance {
            }
            geometry Cylinder {
              height 0.15
              radius 0.3
            }
          }
        ]
        name "wheel_fl"
        boundingObject USE WHEEL
        physics Physics {
        }
      }
    }
    HingeJoint {
      jointParameters HingeJointParameters {
        axis 0 1 0
        anchor -0.5 0.4 -0.15
      }
      device [
        RotationalMotor {
          name "motor_fl"
        }
      ]
      endPoint Solid {
        translation -0.5000000000000001 -0.39999999999999986 -0.15000000000000024
        rotation 0.5773489358556709 0.5773509358554486 0.5773509358554485 2.0943999999999994
        children [
          Shape {
            appearance PBRAppearance {
            }
            geometry Cylinder {
              height 0.15
              radius 0.3
            }
          }
        ]
        name "wheel_bl"
        boundingObject USE WHEEL
        physics Physics {
        }
      }
    }
    HingeJoint {
      jointParameters HingeJointParameters {
        axis 0 1 0
        anchor 0.5 0.4 -0.15
      }
      device [
        RotationalMotor {
          name "motor_fr"
        }
      ]
      endPoint Solid {
        translation 0.5 0.39999999999999986 -0.15000000000000036
        rotation 0.5773489358556709 0.5773509358554486 0.5773509358554485 2.0943999999999994
        children [
          Shape {
            appearance PBRAppearance {
            }
            geometry Cylinder {
              height 0.15
              radius 0.3
            }
          }
        ]
        name "wheel_fr"
        boundingObject USE WHEEL
        physics Physics {
        }
      }
    }
    HingeJoint {
      jointParameters HingeJointParameters {
        axis 0 1 0
        anchor 0.5 -0.4 -0.15
      }
      device [
        RotationalMotor {
          name "motor_br"
        }
      ]
      endPoint Solid {
        translation 0.4999999999999999 -0.4000000000000002 -0.15000000000000024
        rotation 0.5773489358556709 0.5773509358554486 0.5773509358554485 2.0943999999999994
        children [
          Shape {
            appearance PBRAppearance {
            }
            geometry Cylinder {
              height 0.15
              radius 0.3
            }
          }
        ]
        name "wheel_br"
        boundingObject USE WHEEL
        physics Physics {
        }
      }
    }
    DEF BODY Shape {
      appearance PBRAppearance {
        baseColor 0 1 1
      }
      geometry Box {
        size 1 1.4 0.4
      }
    }
  ]
  boundingObject USE BODY
  physics Physics {
  }
}
