#VRML_SIM R2025a utf8

EXTERNPROTO "https://raw.githubusercontent.com/cyberbotics/webots/R2025a/projects/objects/floors/protos/RectangleArena.proto"
EXTERNPROTO "https://raw.githubusercontent.com/cyberbotics/webots/R2025a/projects/objects/backgrounds/protos/TexturedBackground.proto"
EXTERNPROTO "https://raw.githubusercontent.com/cyberbotics/webots/R2025a/projects/objects/backgrounds/protos/TexturedBackgroundLight.proto"
EXTERNPROTO "https://raw.githubusercontent.com/cyberbotics/webots/R2025a/projects/robots/robotis/turtlebot/protos/TurtleBot3Burger.proto"
EXTERNPROTO "https://raw.githubusercontent.com/cyberbotics/webots/R2025a/projects/objects/factory/containers/protos/WoodenBox.proto"

WorldInfo {
  contactProperties [
    ContactProperties {
      material1 "wheel_material_right"
      material2 "floor_material"
      coulombFriction [
        1, 0
      ]
      frictionRotation 0.7071 -0.7071
      bounce 0.1
      softERP 0.8
    }
    ContactProperties {
      material1 "wheel_material_left"
      material2 "floor_material"
      coulombFriction [
        1, 0
      ]
      frictionRotation 0.7071 0.7071
      bounce 0.1
      softERP 0.8
    }
  ]
}
Viewpoint {
  orientation -0.10186255972612308 0.1286521987424795 0.9864444387215976 1.352733909485512
  position -1.1073909206763817 -2.7784749406891853 3.353350423195266
}
RectangleArena {
  contactMaterial "floor_material"
  floorSize 12 20
  wallThickness 0.3
  wallHeight 6
}
TexturedBackground {
}
TexturedBackgroundLight {
}
Robot {
  translation -4.03 -8.93 0.6
  children [
    HingeJoint {
      jointParameters HingeJointParameters {
        anchor -0.62 0.4 -0.15
      }
      device [
        RotationalMotor {
          name "motor_fl"
        }
      ]
      endPoint Solid {
        translation -0.62 0.4 -0.15
        rotation 0 1 0 1.5708
        children [
          DEF WHEEL_FL Shape {
            appearance PBRAppearance {
            }
            geometry Cylinder {
              height 0.2
              radius 0.3
            }
          }
        ]
        name "wheel_fl"
        contactMaterial "wheel_material_left"
        boundingObject Pose {
          children [
            USE WHEEL_FL
          ]
        }
        physics Physics {
          density 1
          mass 1
        }
      }
    }
    HingeJoint {
      jointParameters HingeJointParameters {
        anchor -0.62 -0.4 -0.15
      }
      device [
        RotationalMotor {
          name "motor_bl"
        }
      ]
      endPoint Solid {
        translation -0.62 -0.4 -0.15
        rotation 0 1 0 1.5708
        children [
          DEF WHEEL_BL Shape {
            appearance PBRAppearance {
            }
            geometry Cylinder {
              height 0.2
              radius 0.3
            }
          }
        ]
        name "wheel_bl"
        contactMaterial "wheel_material_right"
        boundingObject Pose {
          children [
            USE WHEEL_BL
          ]
        }
        physics Physics {
          density 1
          mass 1
        }
        locked TRUE
      }
    }
    HingeJoint {
      jointParameters HingeJointParameters {
        anchor 0.62 0.4 -0.15
      }
      device [
        RotationalMotor {
          name "motor_fr"
        }
      ]
      endPoint Solid {
        translation 0.62 0.4 -0.15
        rotation 0 1 0 1.5708
        children [
          DEF WHEEL_FR Shape {
            appearance PBRAppearance {
            }
            geometry Cylinder {
              height 0.2
              radius 0.3
            }
          }
        ]
        name "wheel_fr"
        contactMaterial "wheel_material_right"
        boundingObject Pose {
          children [
            USE WHEEL_FR
          ]
        }
        physics Physics {
          density 1
          mass 1
        }
        locked TRUE
      }
    }
    HingeJoint {
      jointParameters HingeJointParameters {
        anchor 0.62 -0.4 -0.15
      }
      device [
        RotationalMotor {
          name "motor_br"
        }
      ]
      endPoint Solid {
        translation 0.62 -0.4 -0.15
        rotation 0 1 0 1.5708
        children [
          DEF WHEEL_BR Shape {
            appearance PBRAppearance {
            }
            geometry Cylinder {
              height 0.2
              radius 0.3
            }
          }
        ]
        name "wheel_br"
        contactMaterial "wheel_material_left"
        boundingObject Pose {
          children [
            USE WHEEL_BR
          ]
        }
        physics Physics {
          density 1
          mass 1
        }
        locked TRUE
      }
    }
    DEF BODY Shape {
      appearance PBRAppearance {
        baseColor 0 1 1
      }
      geometry Box {
        size 1 1.4 0.4
      }
    }
  ]
  boundingObject USE BODY
  controller "robot_controller"
}
DEF Bot_2 TurtleBot3Burger {
  translation 0 5 0
  rotation 0 0 1 1.5708
  name "Bot_2"
}
DEF Bot_1 TurtleBot3Burger {
  translation -0.3 5 0
  rotation 0 0 1 1.5708
  name "Bot_1"
}
DEF Bot_3 TurtleBot3Burger {
  translation 0.3 5 0
  rotation 0 0 1 1.5708
  name "Bot_3"
}
DEF Aisle_2 Group {
  children [
    DEF Aisle_2_Rack_4 WoodenBox {
      translation 1.2 8.5 0.3
      name "Aisle_2_Rack_4"
      size 1 0.6 1
    }
    DEF Aisle_2_Rack_3 WoodenBox {
      translation 2.3 8.5 0.3
      name "Aisle_2_Rack_3"
      size 1 0.6 1
    }
    DEF Aisle_2_Rack_2 WoodenBox {
      translation 3.4 8.5 0.3
      name "Aisle_2_Rack_2"
      size 1 0.6 1
    }
    DEF Aisle_2_Rack_1 WoodenBox {
      translation 4.5 8.5 0.3
      name "Aisle_2_Rack_1"
      size 1 0.6 1
    }
  ]
}
DEF Aisle_4 Group {
  children [
    DEF Aisle_4_Rack_4 WoodenBox {
      translation 1.2 7.6 0.3
      name "Aisle_4_Rack_4"
      size 1 0.6 1
    }
    DEF Aisle_4_Rack_3 WoodenBox {
      translation 2.3 7.6 0.3
      name "Aisle_4_Rack_3"
      size 1 0.6 1
    }
    DEF Aisle_4_Rack_2 WoodenBox {
      translation 3.4 7.6 0.3
      name "Aisle_4_Rack_2"
      size 1 0.6 1
    }
    DEF Aisle_4_Rack_1 WoodenBox {
      translation 4.5 7.6 0.3
      name "Aisle_4_Rack_1"
      size 1 0.6 1
    }
  ]
}
DEF Aisle_6 Group {
  children [
    DEF Aisle_6_Rack_4 WoodenBox {
      translation 1.2 6.9 0.3
      name "Aisle_6_Rack_4"
      size 1 0.6 1
    }
    DEF Aisle_6_Rack_3 WoodenBox {
      translation 2.3 6.9 0.3
      name "Aisle_6_Rack_3"
      size 1 0.6 1
    }
    DEF Aisle_6_Rack_2 WoodenBox {
      translation 3.4 6.9 0.3
      name "Aisle_6_Rack_2"
      size 1 0.6 1
    }
    DEF Aisle_6_Rack_1 WoodenBox {
      translation 4.5 6.9 0.3
      name "Aisle_6_Rack_1"
      size 1 0.6 1
    }
  ]
}
DEF Aisle_8 Group {
  children [
    DEF Aisle_8_Rack_4 WoodenBox {
      translation 1.2 6 0.3
      name "Aisle_8_Rack_4"
      size 1 0.6 1
    }
    DEF Aisle_8_Rack_3 WoodenBox {
      translation 2.3 6 0.3
      name "Aisle_8_Rack_3"
      size 1 0.6 1
    }
    DEF Aisle_8_Rack_2 WoodenBox {
      translation 3.4 6 0.3
      name "Aisle_8_Rack_2"
      size 1 0.6 1
    }
    DEF Aisle_8_Rack_1 WoodenBox {
      translation 4.5 6 0.3
      name "Aisle_8_Rack_1"
      size 1 0.6 1
    }
  ]
}
DEF Aisle_1 Group {
  children [
    DEF Aisle_1_Rack_4 WoodenBox {
      translation -4.5 8.5 0.3
      name "Aisle_1_Rack_4"
      size 1 0.6 1
    }
    DEF Aisle_1_Rack_3 WoodenBox {
      translation -3.4 8.5 0.3
      name "Aisle_1_Rack_3"
      size 1 0.6 1
    }
    DEF Aisle_1_Rack_2 WoodenBox {
      translation -2.3 8.5 0.3
      name "Aisle_1_Rack_2"
      size 1 0.6 1
    }
    DEF Aisle_1_Rack_1 WoodenBox {
      translation -1.2 8.5 0.3
      name "Aisle_1_Rack_1"
      size 1 0.6 1
    }
  ]
}
DEF Aisle_3 Group {
  children [
    DEF Aisle_3_Rack_4 WoodenBox {
      translation -4.5 7.6 0.3
      name "Aisle_3_Rack_4"
      size 1 0.6 1
    }
    DEF Aisle_3_Rack_3 WoodenBox {
      translation -3.4 7.6 0.3
      name "Aisle_3_Rack_3"
      size 1 0.6 1
    }
    DEF Aisle_3_Rack_2 WoodenBox {
      translation -2.3 7.6 0.3
      name "Aisle_3_Rack_2"
      size 1 0.6 1
    }
    DEF Aisle_3_Rack_1 WoodenBox {
      translation -1.2 7.6 0.3
      name "Aisle_3_Rack_1"
      size 1 0.6 1
    }
  ]
}
DEF Aisle_5 Group {
  children [
    DEF Aisle_5_Rack_4 WoodenBox {
      translation -4.5 6.9 0.3
      name "Aisle_5_Rack_4"
      size 1 0.6 1
    }
    DEF Aisle_5_Rack_3 WoodenBox {
      translation -3.4 6.9 0.3
      name "Aisle_5_Rack_3"
      size 1 0.6 1
    }
    DEF Aisle_5_Rack_2 WoodenBox {
      translation -2.3 6.9 0.3
      name "Aisle_5_Rack_2"
      size 1 0.6 1
    }
    DEF Aisle_5_Rack_1 WoodenBox {
      translation -1.2 6.9 0.3
      name "Aisle_5_Rack_1"
      size 1 0.6 1
    }
  ]
}
DEF Aisle_7 Group {
  children [
    DEF Aisle_7_Rack_4 WoodenBox {
      translation -4.5 6 0.3
      name "Aisle_7_Rack_4"
      size 1 0.6 1
    }
    DEF Aisle_7_Rack_3 WoodenBox {
      translation -3.4 6 0.3
      name "Aisle_7_Rack_3"
      size 1 0.6 1
    }
    DEF Aisle_7_Rack_2 WoodenBox {
      translation -2.3 6 0.3
      name "Aisle_7_Rack_2"
      size 1 0.6 1
    }
    DEF Aisle_7_Rack_1 WoodenBox {
      translation -1.2 6 0.3
      name "Aisle_7_Rack_1"
      size 1 0.6 1
    }
  ]
}
DEF Dropoff Solid {
  translation 0 4 0
  children [
    Shape {
      appearance PBRAppearance {
        baseColor 0 1 1
        metalness 0
      }
      geometry Cylinder {
        height 0.001
        radius 1.5
      }
    }
  ]
}
