#VRML_SIM R2025a utf8

EXTERNPROTO "https://raw.githubusercontent.com/cyberbotics/webots/R2025a/projects/objects/floors/protos/RectangleArena.proto"
EXTERNPROTO "https://raw.githubusercontent.com/cyberbotics/webots/R2025a/projects/objects/backgrounds/protos/TexturedBackground.proto"
EXTERNPROTO "https://raw.githubusercontent.com/cyberbotics/webots/R2025a/projects/objects/backgrounds/protos/TexturedBackgroundLight.proto"

WorldInfo {
  contactProperties [
    ContactProperties {
      material1 "wheel_material"
      coulombFriction [
        1, 0
      ]
      forceDependentSlip [
        0, 0
      ]
    }
  ]
}
Viewpoint {
  orientation -0.1210850297873183 0.40611326621096683 0.9057651078336285 0.6360313281102905
  position -12.043482974107908 -7.034256669187277 5.641204790534352
}
RectangleArena {
  floorSize 30 50
  wallThickness 0.3
  wallHeight 6
}
TexturedBackground {
}
TexturedBackgroundLight {
}
Robot {
  translation 0 0 1
  children [
    HingeJoint {
      jointParameters HingeJointParameters {
        anchor -0.5 0.4 -0.15
      }
      device [
        RotationalMotor {
          name "motor_fl"
        }
      ]
      endPoint Solid {
        translation -0.4999999999999999 0.4000000000000002 -0.15000000000000036
        rotation 0.5773489358556707 0.5773509358554485 0.5773509358554487 2.0943999999999994
        children [
          DEF WHEEL Shape {
            appearance PBRAppearance {
            }
            geometry Cylinder {
              height 0.15
              radius 0.3
            }
          }
        ]
        name "wheel_fl"
        contactMaterial "wheel_material"
        boundingObject USE WHEEL
        physics Physics {
        }
      }
    }
    HingeJoint {
      jointParameters HingeJointParameters {
        anchor -0.5 -0.4 -0.15
      }
      device [
        RotationalMotor {
          name "motor_bl"
        }
      ]
      endPoint Solid {
        translation -0.5 -0.4 -0.15
        rotation 0.5773489358556707 0.5773509358554485 0.5773509358554487 2.0943999999999994
        children [
          DEF WHEEL Shape {
            appearance PBRAppearance {
            }
            geometry Cylinder {
              height 0.15
              radius 0.3
            }
          }
        ]
        name "wheel_bl"
        contactMaterial "wheel_material"
        boundingObject USE WHEEL
        physics Physics {
        }
      }
    }
    HingeJoint {
      jointParameters HingeJointParameters {
        anchor 0.5 0.4 -0.15
      }
      device [
        RotationalMotor {
          name "motor_fr"
        }
      ]
      endPoint Solid {
        translation 0.49999998574856314 0.3978335800111345 -0.15036783503706297
        rotation 0.577348933179372 0.5773509373270198 0.5773509370601668 2.0944000044147275
        children [
          Shape {
            appearance PBRAppearance {
            }
            geometry Cylinder {
              height 0.15
              radius 0.3
            }
          }
        ]
        name "wheel_fr"
        contactMaterial "wheel_material"
        boundingObject USE WHEEL
        physics Physics {
        }
      }
    }
    HingeJoint {
      jointParameters HingeJointParameters {
        anchor 0.5 -0.4 -0.15
      }
      device [
        RotationalMotor {
          name "motor_br"
        }
      ]
      endPoint Solid {
        translation 0.5000000111545416 -0.4021859390136936 -0.15022479254207255
        rotation 0.5773489364235762 0.5773509366893266 0.5773509344536669 2.0944000025016534
        children [
          Shape {
            appearance PBRAppearance {
            }
            geometry Cylinder {
              height 0.15
              radius 0.3
            }
          }
        ]
        name "wheel_br"
        contactMaterial "wheel_material"
        boundingObject USE WHEEL
        physics Physics {
        }
      }
    }
    DEF BODY Shape {
      appearance PBRAppearance {
        baseColor 0 1 1
      }
      geometry Box {
        size 1 1.4 0.4
      }
    }
  ]
  boundingObject USE BODY
  physics Physics {
  }
  controller "robot_controller"
}
