#VRML_SIM R2025a utf8

EXTERNPROTO "https://raw.githubusercontent.com/cyberbotics/webots/R2025a/projects/objects/floors/protos/RectangleArena.proto"
EXTERNPROTO "https://raw.githubusercontent.com/cyberbotics/webots/R2025a/projects/objects/backgrounds/protos/TexturedBackground.proto"
EXTERNPROTO "https://raw.githubusercontent.com/cyberbotics/webots/R2025a/projects/objects/backgrounds/protos/TexturedBackgroundLight.proto"

WorldInfo {
}
Viewpoint {
  orientation -0.2013570191279302 0.03893976820487711 0.9787436054963857 2.767480571898003
  position 10.124746614130148 -5.448191582822125 7.24137174068561
}
RectangleArena {
  floorSize 30 50
  wallThickness 0.3
  wallHeight 6
}
TexturedBackground {
}
TexturedBackgroundLight {
}
Robot {
  translation 0 0 1
  children [
    HingeJoint {
      jointParameters HingeJointParameters {
        axis 0 1 0
        anchor -0.5 0.4 -0.15
      }
      device [
        RotationalMotor {
          name "motor_fl"
        }
      ]
      endPoint Solid {
        translation -0.5 0.4 -0.15
        rotation 0.5773489358556708 0.5773509358554485 0.5773509358554485 2.0944
        children [
          Shape {
            appearance PBRAppearance {
            }
            geometry Cylinder {
              height 0.15
              radius 0.3
            }
          }
        ]
        name "wheel_fl"
        physics Physics {
        }
      }
    }
    HingeJoint {
      jointParameters HingeJointParameters {
        axis 0 1 0
        anchor -0.5 -0.4 -0.15
      }
      device [
        RotationalMotor {
          name "motor_bl"
        }
      ]
      endPoint Solid {
        translation -0.5 -0.4 -0.15
        rotation 0.5773489358556708 0.5773509358554485 0.5773509358554485 2.0944
        children [
          Shape {
            appearance PBRAppearance {
            }
            geometry Cylinder {
              height 0.15
              radius 0.3
            }
          }
        ]
        name "wheel_bl"
        physics Physics {
        }
      }
    }
    HingeJoint {
      jointParameters HingeJointParameters {
        axis 0 1 0
        anchor 0.5 0.4 -0.15
      }
      device [
        RotationalMotor {
          name "motor_fr"
        }
      ]
      endPoint Solid {
        translation 0.5 0.4 -0.15
        rotation 0.5773489358556708 0.5773509358554485 0.5773509358554485 2.0944
        children [
          Shape {
            appearance PBRAppearance {
            }
            geometry Cylinder {
              height 0.15
              radius 0.3
            }
          }
        ]
        name "wheel_fr"
        physics Physics {
        }
      }
    }
    HingeJoint {
      jointParameters HingeJointParameters {
        axis 0 1 0
        anchor 0.5 -0.4 -0.15
      }
      device [
        RotationalMotor {
          name "motor_br"
        }
      ]
      endPoint Solid {
        translation 0.5 -0.4 -0.15
        rotation 0.5773489358556708 0.5773509358554485 0.5773509358554485 2.0944
        children [
          Shape {
            appearance PBRAppearance {
            }
            geometry Cylinder {
              height 0.15
              radius 0.3
            }
          }
        ]
        name "wheel_br"
        physics Physics {
        }
      }
    }
    Shape {
      appearance PBRAppearance {
        baseColor 0 1 1
      }
      geometry Box {
        size 1 1.4 0.4
      }
    }
  ]
  physics Physics {
  }
}
