#VRML_SIM R2025a utf8

EXTERNPROTO "https://raw.githubusercontent.com/cyberbotics/webots/R2025a/projects/objects/floors/protos/RectangleArena.proto"
EXTERNPROTO "https://raw.githubusercontent.com/cyberbotics/webots/R2025a/projects/objects/backgrounds/protos/TexturedBackground.proto"
EXTERNPROTO "https://raw.githubusercontent.com/cyberbotics/webots/R2025a/projects/objects/backgrounds/protos/TexturedBackgroundLight.proto"

WorldInfo {
  contactProperties [
    ContactProperties {
      material1 "wheel_material_right"
      material2 "floor_material"
      coulombFriction [
        1, 0
      ]
      frictionRotation 0.7071 -0.7071
      bounce 0.1
      softERP 0.8
    }
    ContactProperties {
      material1 "wheel_material_left"
      material2 "floor_material"
      coulombFriction [
        1, 0
      ]
      frictionRotation 0.7071 0.7071
      bounce 0.1
      softERP 0.8
    }
  ]
}
Viewpoint {
  orientation 0.1677569301228658 -0.16850491405777016 -0.9713205991505253 4.68772473732308
  position -0.35424259128675534 -4.575488252738241 2.2541795728135963
}
RectangleArena {
  contactMaterial "floor_material"
  floorSize 30 50
  wallThickness 0.3
  wallHeight 6
}
TexturedBackground {
}
TexturedBackgroundLight {
}
Robot {
  translation 0 0 0.6
  children [
    HingeJoint {
      jointParameters HingeJointParameters {
        anchor -0.62 0.4 -0.15
      }
      device [
        RotationalMotor {
          name "motor_fl"
        }
      ]
      endPoint Solid {
        translation -0.62 0.4 -0.15
        rotation 0 1 0 1.5708
        children [
          DEF WHEEL_FL Shape {
            appearance PBRAppearance {
            }
            geometry Cylinder {
              height 0.2
              radius 0.3
            }
          }
        ]
        name "wheel_fl"
        contactMaterial "wheel_material_left"
        boundingObject Pose {
          children [
            USE WHEEL_FL
          ]
        }
        physics Physics {
          density 1
          mass 1
        }
      }
    }
    HingeJoint {
      jointParameters HingeJointParameters {
        anchor -0.62 -0.4 -0.15
      }
      device [
        RotationalMotor {
          name "motor_bl"
        }
      ]
      endPoint Solid {
        translation -0.62 -0.4 -0.15
        rotation 0 1 0 1.5708
        children [
          DEF WHEEL_BL Shape {
            appearance PBRAppearance {
            }
            geometry Cylinder {
              height 0.2
              radius 0.3
            }
          }
        ]
        name "wheel_bl"
        contactMaterial "wheel_material_right"
        boundingObject Pose {
          children [
            USE WHEEL_BL
          ]
        }
        physics Physics {
          density 1
          mass 1
        }
        locked TRUE
      }
    }
    HingeJoint {
      jointParameters HingeJointParameters {
        anchor 0.62 0.4 -0.15
      }
      device [
        RotationalMotor {
          name "motor_fr"
        }
      ]
      endPoint Solid {
        translation 0.62 0.4 -0.15
        rotation 0 1 0 1.5708
        children [
          DEF WHEEL_FR Shape {
            appearance PBRAppearance {
            }
            geometry Cylinder {
              height 0.2
              radius 0.3
            }
          }
        ]
        name "wheel_fr"
        contactMaterial "wheel_material_right"
        boundingObject Pose {
          children [
            USE WHEEL_FR
          ]
        }
        physics Physics {
          density 1
          mass 1
        }
        locked TRUE
      }
    }
    HingeJoint {
      jointParameters HingeJointParameters {
        anchor 0.62 -0.4 -0.15
      }
      device [
        RotationalMotor {
          name "motor_br"
        }
      ]
      endPoint Solid {
        translation 0.62 -0.4 -0.15
        rotation 0 1 0 1.5708
        children [
          DEF WHEEL_BR Shape {
            appearance PBRAppearance {
            }
            geometry Cylinder {
              height 0.2
              radius 0.3
            }
          }
        ]
        name "wheel_br"
        contactMaterial "wheel_material_left"
        boundingObject Pose {
          children [
            USE WHEEL_BR
          ]
        }
        physics Physics {
          density 1
          mass 1
        }
        locked TRUE
      }
    }
    DEF BODY Shape {
      appearance PBRAppearance {
        baseColor 0 1 1
      }
      geometry Box {
        size 1 1.4 0.4
      }
    }
  ]
  boundingObject USE BODY
  physics Physics {
    density 1
    mass 1
  }
  controller "robot_controller"
}
