#VRML_SIM R2025a utf8

EXTERNPROTO "https://raw.githubusercontent.com/cyberbotics/webots/R2025a/projects/objects/floors/protos/RectangleArena.proto"
EXTERNPROTO "https://raw.githubusercontent.com/cyberbotics/webots/R2025a/projects/objects/backgrounds/protos/TexturedBackground.proto"
EXTERNPROTO "https://raw.githubusercontent.com/cyberbotics/webots/R2025a/projects/objects/backgrounds/protos/TexturedBackgroundLight.proto"

WorldInfo {
}
Viewpoint {
  orientation -0.26654362959304834 0.2366340721577656 0.9343226473854719 1.7566837105611837
  position -1.7380652974964037 -10.96912616205845 9.097626139239813
}
RectangleArena {
  floorSize 30 50
  wallThickness 0.3
  wallHeight 6
}
TexturedBackground {
}
TexturedBackgroundLight {
}
Robot {
  translation 0 0 1
  children [
    HingeJoint {
      jointParameters HingeJointParameters {
        axis 0 1 0
        anchor -0.5 0.4 -0.15
      }
      device [
        RotationalMotor {
          name "motor_fl"
        }
      ]
      endPoint Solid {
        translation -0.5 0.4 -0.15
        rotation 0.5773489358556708 0.5773509358554485 0.5773509358554485 2.0944
        children [
          Shape {
            appearance PBRAppearance {
            }
            geometry Cylinder {
              height 0.15
              radius 0.3
            }
          }
        ]
        name "wheel_fl"
        physics Physics {
        }
      }
    }
    Shape {
      appearance PBRAppearance {
        baseColor 0 1 1
      }
      geometry Box {
        size 1 1.4 0.4
      }
    }
  ]
  physics Physics {
  }
}
