#VRML_SIM R2025a utf8

EXTERNPROTO "https://raw.githubusercontent.com/cyberbotics/webots/R2025a/projects/objects/floors/protos/RectangleArena.proto"
EXTERNPROTO "https://raw.githubusercontent.com/cyberbotics/webots/R2025a/projects/objects/backgrounds/protos/TexturedBackground.proto"
EXTERNPROTO "https://raw.githubusercontent.com/cyberbotics/webots/R2025a/projects/objects/backgrounds/protos/TexturedBackgroundLight.proto"
EXTERNPROTO "https://raw.githubusercontent.com/cyberbotics/webots/R2025a/projects/robots/robotis/turtlebot/protos/TurtleBot3Burger.proto"
EXTERNPROTO "https://raw.githubusercontent.com/cyberbotics/webots/R2025a/projects/objects/factory/containers/protos/WoodenBox.proto"

WorldInfo {
  contactProperties [
    ContactProperties {
      material1 "wheel_material_right"
      material2 "floor_material"
      coulombFriction [
        1, 0
      ]
      frictionRotation 0.7071 -0.7071
      bounce 0.1
      softERP 0.8
    }
    ContactProperties {
      material1 "wheel_material_left"
      material2 "floor_material"
      coulombFriction [
        1, 0
      ]
      frictionRotation 0.7071 0.7071
      bounce 0.1
      softERP 0.8
    }
  ]
}
Viewpoint {
  orientation -0.5324992453114222 -0.017733836719761045 0.8462446837516693 3.1979480728892495
  position 17.203951480355247 6.339216943957926 27.15121970561814
}
RectangleArena {
  contactMaterial "floor_material"
  floorSize 12 20
  wallThickness 0.3
  wallHeight 6
}
TexturedBackground {
}
TexturedBackgroundLight {
}
Robot {
  translation 0 0 0.6
  children [
    HingeJoint {
      jointParameters HingeJointParameters {
        anchor -0.62 0.4 -0.15
      }
      device [
        RotationalMotor {
          name "motor_fl"
        }
      ]
      endPoint Solid {
        translation -0.62 0.4 -0.15
        rotation 0 1 0 1.5708
        children [
          DEF WHEEL_FL Shape {
            appearance PBRAppearance {
            }
            geometry Cylinder {
              height 0.2
              radius 0.3
            }
          }
        ]
        name "wheel_fl"
        contactMaterial "wheel_material_left"
        boundingObject Pose {
          children [
            USE WHEEL_FL
          ]
        }
        physics Physics {
          density 1
          mass 1
        }
      }
    }
    HingeJoint {
      jointParameters HingeJointParameters {
        anchor -0.62 -0.4 -0.15
      }
      device [
        RotationalMotor {
          name "motor_bl"
        }
      ]
      endPoint Solid {
        translation -0.62 -0.4 -0.15
        rotation 0 1 0 1.5708
        children [
          DEF WHEEL_BL Shape {
            appearance PBRAppearance {
            }
            geometry Cylinder {
              height 0.2
              radius 0.3
            }
          }
        ]
        name "wheel_bl"
        contactMaterial "wheel_material_right"
        boundingObject Pose {
          children [
            USE WHEEL_BL
          ]
        }
        physics Physics {
          density 1
          mass 1
        }
        locked TRUE
      }
    }
    HingeJoint {
      jointParameters HingeJointParameters {
        anchor 0.62 0.4 -0.15
      }
      device [
        RotationalMotor {
          name "motor_fr"
        }
      ]
      endPoint Solid {
        translation 0.62 0.4 -0.15
        rotation 0 1 0 1.5708
        children [
          DEF WHEEL_FR Shape {
            appearance PBRAppearance {
            }
            geometry Cylinder {
              height 0.2
              radius 0.3
            }
          }
        ]
        name "wheel_fr"
        contactMaterial "wheel_material_right"
        boundingObject Pose {
          children [
            USE WHEEL_FR
          ]
        }
        physics Physics {
          density 1
          mass 1
        }
        locked TRUE
      }
    }
    HingeJoint {
      jointParameters HingeJointParameters {
        anchor 0.62 -0.4 -0.15
      }
      device [
        RotationalMotor {
          name "motor_br"
        }
      ]
      endPoint Solid {
        translation 0.62 -0.4 -0.15
        rotation 0 1 0 1.5708
        children [
          DEF WHEEL_BR Shape {
            appearance PBRAppearance {
            }
            geometry Cylinder {
              height 0.2
              radius 0.3
            }
          }
        ]
        name "wheel_br"
        contactMaterial "wheel_material_left"
        boundingObject Pose {
          children [
            USE WHEEL_BR
          ]
        }
        physics Physics {
          density 1
          mass 1
        }
        locked TRUE
      }
    }
    DEF BODY Shape {
      appearance PBRAppearance {
        baseColor 0 1 1
      }
      geometry Box {
        size 1 1.4 0.4
      }
    }
  ]
  boundingObject USE BODY
  controller "robot_controller"
}
TurtleBot3Burger {
  translation -2.61 1.36 0
}
DEF Aisle_2 Group {
  children [
    WoodenBox {
      translation 1.2 8.5 0.3
      name "wooden box(3)"
      size 1 0.6 1
    }
    WoodenBox {
      translation 2.3 8.5 0.3
      name "wooden box(2)"
      size 1 0.6 1
    }
    WoodenBox {
      translation 3.4 8.5 0.3
      name "wooden box(1)"
      size 1 0.6 1
    }
    WoodenBox {
      translation 4.5 8.5 0.3
      name "wooden box(8)"
      size 1 0.6 1
    }
  ]
}
DEF Aisle_4 Group {
  children [
    WoodenBox {
      translation 1.2 7.6 0.3
      name "wooden box(2)"
      size 1 0.6 1
    }
    WoodenBox {
      translation 2.3 7.6 0.3
      name "wooden box(2)"
      size 1 0.6 1
    }
    WoodenBox {
      translation 3.4 7.6 0.3
      name "wooden box(3)"
      size 1 0.6 1
    }
    WoodenBox {
      translation 4.5 7.6 0.3
      name "wooden box(3)"
      size 1 0.6 1
    }
  ]
}
DEF Aisle_6 Group {
  children [
    WoodenBox {
      translation 1.2 6.9 0.3
      name "wooden box(3)"
      size 1 0.6 1
    }
    WoodenBox {
      translation 2.3 6.9 0.3
      name "wooden box(3)"
      size 1 0.6 1
    }
    WoodenBox {
      translation 3.4 6.9 0.3
      name "wooden box(3)"
      size 1 0.6 1
    }
    WoodenBox {
      translation 4.5 6.9 0.3
      name "wooden box(3)"
      size 1 0.6 1
    }
  ]
}
DEF Aisle_8 Group {
  children [
    WoodenBox {
      translation 1.2 6 0.3
      name "wooden box(3)"
      size 1 0.6 1
    }
    WoodenBox {
      translation 2.3 6 0.3
      name "wooden box(3)"
      size 1 0.6 1
    }
    WoodenBox {
      translation 3.4 6 0.3
      name "wooden box(3)"
      size 1 0.6 1
    }
    WoodenBox {
      translation 4.5 6 0.3
      name "wooden box(3)"
      size 1 0.6 1
    }
  ]
}
DEF Aisle_1 Group {
  children [
    WoodenBox {
      translation -4.5 8.5 0.3
      name "wooden box(7)"
      size 1 0.6 1
    }
    WoodenBox {
      translation -3.4 8.5 0.3
      name "wooden box(6)"
      size 1 0.6 1
    }
    WoodenBox {
      translation -2.3 8.5 0.3
      name "wooden box(5)"
      size 1 0.6 1
    }
    WoodenBox {
      translation -1.2 8.5 0.3
      name "wooden box(4)"
      size 1 0.6 1
    }
  ]
}
DEF Aisle_3 Group {
  children [
    WoodenBox {
      translation -4.5 7.6 0.3
      name "wooden box(5)"
      size 1 0.6 1
    }
    WoodenBox {
      translation -3.4 7.6 0.3
      name "wooden box(5)"
      size 1 0.6 1
    }
    WoodenBox {
      translation -2.3 7.6 0.3
      name "wooden box(5)"
      size 1 0.6 1
    }
    WoodenBox {
      translation -1.2 7.6 0.3
      name "wooden box(6)"
      size 1 0.6 1
    }
  ]
}
DEF Aisle_5 Group {
  children [
    WoodenBox {
      translation -4.5 6.9 0.3
      name "wooden box(3)"
      size 1 0.6 1
    }
    WoodenBox {
      translation -3.4 6.9 0.3
      name "wooden box(3)"
      size 1 0.6 1
    }
    WoodenBox {
      translation -2.3 6.9 0.3
      name "wooden box(3)"
      size 1 0.6 1
    }
    WoodenBox {
      translation -1.2 6.9 0.3
      name "wooden box(3)"
      size 1 0.6 1
    }
  ]
}
DEF Aisle_7 Group {
  children [
    WoodenBox {
      translation -4.5 6 0.3
      name "wooden box(3)"
      size 1 0.6 1
    }
    WoodenBox {
      translation -3.4 6 0.3
      name "wooden box(3)"
      size 1 0.6 1
    }
    WoodenBox {
      translation -2.3 6 0.3
      name "wooden box(3)"
      size 1 0.6 1
    }
    WoodenBox {
      translation -1.2 6 0.3
      name "wooden box(3)"
      size 1 0.6 1
    }
  ]
}
